Workbook

Sheet README
A1: Egypt Crop Water Requirement — Validation Reference Workbook
A3: Purpose: reference data to validate the water-budget constraint of a crop-mix optimization system against published sources.
A5: Sheet guide:
A6: 1. Seasonal_ETcrop_Range — FAO Irrigation & Drainage Paper 24, Table 20. Quick plausibility check: total seasonal water use range (mm) per crop, ~29 crops, generic/global. Use this for a fast sanity check with no calculation needed.
A7: 2. Kc_Values — FAO Irrigation & Drainage Paper 24, Table 21. Crop coefficients (Kc) for mid-season and end-season stages, split by humidity/wind class. Egypt = arid, use the 'RHmin<20%' columns. ~35 crops.
A8: 3. Growth_Stage_Lengths — FAO Irrigation & Drainage Paper 24, Table 22. Typical initial/development/mid-season/late-season stage lengths (days) by crop and example region, several explicitly reference Egypt.
A9: 4. Sinai_Egypt_NIWR — Gabr & Fattouh (2021), Ain Shams Engineering Journal. Egypt-measured (not generic) net irrigation water requirement for 8 crops across two Sinai agro-ecological regions (AER1 clay / AER2 sandy). Stronger evidence where it overlaps with your crops, but narrow geographic coverage.
A10: 5. Worked_Example_ETc_Calc — a live formula template showing how Kc and ETo combine into a real seasonal water requirement, stage by stage, rather than a single constant number. Edit the yellow cells with your farmer's real location/ETo data.
A12: IMPORTANT — why there is no single 'ETc value' per crop:
A13: Crop water need is NOT a constant. It is ETc(t) = Kc(t) x ETo(t), where both terms vary through the season:
A14: - Kc (crop coefficient) changes across four growth stages: initial -> development -> mid-season -> late-season.
A15: - ETo (reference evapotranspiration) changes day to day with temperature, humidity, wind, and solar radiation.
... A21: - Worked example ETo values are ILLUSTRATIVE placeholders, not sourced Egyptian weather data — replace before using real conclusions.

Sheet Egypt_Ag_Seasons_Reference
A1: Egypt's agricultural seasons and typical crops
A3: Season (English) | B3: Season (local term) | C3: Typical months | D3: Typical crops (examples) | E3: Notes
A4: Winter | B4: Shtwi (شتوي) | C4: ~November - April/May | D4: Wheat, berseem clover, faba beans, barley, onion, garlic, sugar beet | E4: Egypt's main cereal and clover season; berseem is the dominant winter livestock fodder crop.
A5: Summer | B5: Sayfi (صيفي) | C5: ~April/May - September/October | D5: Cotton, rice, summer maize, soybean, sesame, sunflower, peanuts, summer vegetables (tomato) | E5: Highest water demand season; cotton and rice are the classic large-area summer crops.
A6: Nili | B6: Nili (نيلي) | C6: ~July/August - November | D6: Nili maize, sorghum, some vegetables | E6: Historic flood-season planting (named after the Nile flood); much smaller area today post-Aswan High Dam, but still used administratively, mainly for a second maize crop.
A7: Perennial / multi-season | B7: - | C7: Year-round (12-24 month cycle) | D7: Sugarcane, banana, some fruit orchards | E7: Does not fit a single season. Sugarcane in Egypt is grown almost entirely in Upper Egypt (Qena, Aswan, Luxor) on ratoon cycles of ~12 months.
A9: Note: many crops (e.g. tomato, potato) are grown in more than one season depending on region and variety. This table shows the DOMINANT/classic season per crop for a typical smallholding, not an exhaustive planting calendar.

Sheet Zone_ETo_Assumptions
A1: Major Egyptian agricultural zones - reference evapotranspiration (ETo) assumptions
A2: CAUTION: the ETo values below are APPROXIMATE, general-knowledge placeholders reflecting Egypt's known north-south climate gradient (Delta = milder/more humid, Upper Egypt = hotter/drier). They are NOT extracted from a specific measured source for this workbook. Replace the yellow cells with real station data (e.g. from the CROPWAT-Egypt zone study, or a live source like NASA POWER) before relying on the Estimated rows for anything beyond a first-pass sanity check.
A4: Zone | B4: Governorates (examples) | C4: Climate character | D4: Winter ETo (mm/day) [EDIT ME] | E4: Summer ETo (mm/day) [EDIT ME] | F4: Nili ETo (mm/day) [EDIT ME]
A5: Delta | B5: Dakahlia, Gharbia, Kafr El-Sheikh, Beheira, Sharqia, Monufia, Qalyubia, Damietta | C5: Mediterranean-influenced, more humid, milder | D5: 2.7 | E5: 5.2 | F5: 4.3
A6: Middle Egypt | B6: Fayoum, Beni Suef, Minya | C6: Transitional desert climate | D6: 3 | E6: 6 | F6: 5
A7: Upper Egypt | B7: Sohag, Qena, Luxor, Aswan | C7: Hot arid desert, low humidity, high ETo - hottest/driest zone in Egypt | D7: 3.6 | E7: 7.5 | F7: 6.3
A8: Sinai / Reclaimed Lands | B8: North Sinai, Ismailia, New Valley, desert-fringe reclaimed land | C8: Sandy soils, more wind exposure, variable | D8: 3 | E8: 6.5 | F8: 5.4

Sheet Ready_Lookup_Water_by_Crop
A1: Ready-to-use lookup: water requirement by crop, Egyptian season, and zone
A2: Green rows = MEASURED (Gabr & Fattouh 2021, Sinai only). Orange rows = ESTIMATED (Kc x zone ETo x typical season length, single mid-season-Kc approximation - not a full 4-stage curve like the Worked_Example sheet). Use Measured rows as ground truth where available; use Estimated rows for broader zone/crop coverage with lower confidence.
A4: Crop | B4: Season | C4: Zone | D4: Data Quality | E4: ETo used (mm/day) | F4: Kc (mid-season, arid) | G4: Typical season length (days) | H4: Estimated seasonal water requirement (mm) | I4: Estimated (m3/feddan) | J4: Source | K4: Notes
A5: Wheat | B5: Winter | C5: Sinai - El-Kantara (AER2, sandy) | D5: MEASURED | E5: n/a | F5: n/a | G5: n/a | H5: 263 | I5: =H5*10*0.42 -> 1104.6 | J5: Gabr & Fattouh 2021 | K5: Directly measured via CROPWAT8 for this exact region - highest confidence row in this sheet.
A6: Barley | B6: Winter | C6: Sinai - El-Kantara (AER2, sandy) | D6: MEASURED | E6: n/a | F6: n/a | G6: n/a | H6: 267 | I6: =H6*10*0.42 -> 1121.4 | J6: Gabr & Fattouh 2021 | K6: Directly measured via CROPWAT8 for this exact region - highest confidence row in this sheet.
A7: Barley | B7: Winter | C7: Sinai - Tina Plain (AER1, clay) | D7: MEASURED | E7: n/a | F7: n/a | G7: n/a | H7: 283 | I7: =H7*10*0.42 -> 1188.6 | J7: Gabr & Fattouh 2021 | K7: Directly measured via CROPWAT8 for this exact region - highest confidence row in this sheet.
A8: Berseem clover | B8: Winter | C8: Sinai - El-Kantara (AER2, sandy) | D8: MEASURED | E8: n/a | F8: n/a | G8: n/a | H8: 702 | I8: =H8*10*0.42 -> 2948.4 | J8: Gabr & Fattouh 2021 | K8: Directly measured via CROPWAT8 for this exact region - highest confidence row in this sheet.
A9: Berseem clover | B9: Winter | C9: Sinai - Tina Plain (AER1, clay) | D9: MEASURED | E9: n/a | F9: n/a | G9: n/a | H9: 612 | I9: =H9*10*0.42 -> 2570.4 | J9: Gabr & Fattouh 2021 | K9: Directly measured via CROPWAT8 for this exact region - highest confidence row in this sheet.
A10: Tomato | B10: Winter | C10: Sinai - El-Kantara (AER2, sandy) | D10: MEASURED | E10: n/a | F10: n/a | G10: n/a | H10: 448 | I10: =H10*10*0.42 -> 1881.6 | J10: Gabr & Fattouh 2021 | K10: Directly measured via CROPWAT8 for this exact region - highest confidence row in this sheet.
A11: Tomato | B11: Summer | C11: Sinai - Tina Plain (AER1, clay) | D11: MEASURED | E11: n/a | F11: n/a | G11: n/a | H11: 711 | I11: =H11*10*0.42 -> 2986.2 | J11: Gabr & Fattouh 2021 | K11: Directly measured via CROPWAT8 for this exact region - highest confidence row in this sheet.
A12: Tomato | B12: Summer | C12: Sinai - El-Kantara (AER2, sandy) | D12: MEASURED | E12: n/a | F12: n/a | G12: n/a | H12: 884 | I12: =H12*10*0.42 -> 3712.8 | J12: Gabr & Fattouh 2021 | K12: Directly measured via CROPWAT8 for this exact region - highest confidence row in this sheet.
A13: Cotton | B13: Summer | C13: Sinai - Tina Plain (AER1, clay) | D13: MEASURED | E13: n/a | F13: n/a | G13: n/a | H13: 884 | I13: =H13*10*0.42 -> 3712.8 | J13: Gabr & Fattouh 2021 | K13: Directly measured via CROPWAT8 for this exact region - highest confidence row in this sheet.
A14: Cotton | B14: Summer | C14: Sinai - Tina Plain (AER1, clay) [cross-check] | D14: MEASURED | E14: n/a | F14: n/a | G14: n/a | H14: 901 | I14: =H14*10*0.42 -> 3784.2 | J14: Gabr & Fattouh 2021 (companion paper) | K14: Directly measured via CROPWAT8 for this exact region - highest confidence row in this sheet.
A15: Cotton | B15: Summer | C15: Sinai - El-Kantara (AER2, sandy) | D15: MEASURED | E15: n/a | F15: n/a | G15: n/a | H15: 1107 | I15: =H15*10*0.42 -> 4649.4 | J15: Gabr & Fattouh 2021 | K15: Directly measured via CROPWAT8 for this exact region - highest confidence row in this sheet.
A16: Maize | B16: Summer | C16: Sinai - Tina Plain (AER1, clay) | D16: MEASURED | E16: n/a | F16: n/a | G16: n/a | H16: 576 | I16: =H16*10*0.42 -> 2419.2 | J16: Gabr & Fattouh 2021 | K16: Directly measured via CROPWAT8 for this exact region - highest confidence row in this sheet.
... A20: Greenbeans | B20: Winter | C20: Sinai - El-Kantara (AER2, sandy) | D20: MEASURED | E20: n/a | F20: n/a | G20: n/a | H20: 211 | I20: =H20*10*0.42 -> 886.2 | J20: Gabr & Fattouh 2021 | K20: Directly measured via CROPWAT8 for this exact region - highest confidence row in this sheet.
A21: Wheat | B21: Winter | C21: Delta | D21: ESTIMATED | E21: =INDEX(Zone_ETo_Assumptions!D5:D8,MATCH("Delta",Zone_ETo_Assumptions!$A$5:$A$8,0)) -> 2.7 | F21: =SUMPRODUCT((Kc_Values!$A$2:$A$75="Wheat")*(Kc_Values!$B$2:$B$75="mid_season")*Kc_Values!$E$2:$E$75) -> 1.15 | G21: 145 | H21: =E21*F21*G21 -> 450.225 | I21: =H21*10*0.42 -> 1890.945 | J21: Calculated: FAO24 Table 21 Kc x Zone_ETo_Assumptions x typical season length | K21: Single mid-season-Kc approximation, not a full 4-stage curve - treat as a first-pass estimate, refine using Worked_Example_ETc_Calc method for final numbers.
A22: Wheat | B22: Winter | C22: Middle Egypt | D22: ESTIMATED | E22: =INDEX(Zone_ETo_Assumptions!D5:D8,MATCH("Middle Egypt",Zone_ETo_Assumptions!$A$5:$A$8,0)) -> 3 | F22: =SUMPRODUCT((Kc_Values!$A$2:$A$75="Wheat")*(Kc_Values!$B$2:$B$75="mid_season")*Kc_Values!$E$2:$E$75) -> 1.15 | G22: 145 | H22: =E22*F22*G22 -> 500.25 | I22: =H22*10*0.42 -> 2101.05 | J22: Calculated: FAO24 Table 21 Kc x Zone_ETo_Assumptions x typical season length | K22: Single mid-season-Kc approximation, not a full 4-stage curve - treat as a first-pass estimate, refine using Worked_Example_ETc_Calc method for final numbers.
A23: Wheat | B23: Winter | C23: Upper Egypt | D23: ESTIMATED | E23: =INDEX(Zone_ETo_Assumptions!D5:D8,MATCH("Upper Egypt",Zone_ETo_Assumptions!$A$5:$A$8,0)) -> 3.6 | F23: =SUMPRODUCT((Kc_Values!$A$2:$A$75="Wheat")*(Kc_Values!$B$2:$B$75="mid_season")*Kc_Values!$E$2:$E$75) -> 1.15 | G23: 145 | H23: =E23*F23*G23 -> 600.3 | I23: =H23*10*0.42 -> 2521.26 | J23: Calculated: FAO24 Table 21 Kc x Zone_ETo_Assumptions x typical season length | K23: Single mid-season-Kc approximation, not a full 4-stage curve - treat as a first-pass estimate, refine using Worked_Example_ETc_Calc method for final numbers.
A24: Wheat | B24: Winter | C24: Sinai / Reclaimed Lands | D24: ESTIMATED | E24: =INDEX(Zone_ETo_Assumptions!D5:D8,MATCH("Sinai / Reclaimed Lands",Zone_ETo_Assumptions!$A$5:$A$8,0)) -> 3 | F24: =SUMPRODUCT((Kc_Values!$A$2:$A$75="Wheat")*(Kc_Values!$B$2:$B$75="mid_season")*Kc_Values!$E$2:$E$75) -> 1.15 | G24: 145 | H24: =E24*F24*G24 -> 500.25 | I24: =H24*10*0.42 -> 2101.05 | J24: Calculated: FAO24 Table 21 Kc x Zone_ETo_Assumptions x typical season length | K24: Single mid-season-Kc approximation, not a full 4-stage curve - treat as a first-pass estimate, refine using Worked_Example_ETc_Calc method for final numbers.
A25: Faba beans (proxy: Beans dry/Pulses) | B25: Winter | C25: Delta | D25: ESTIMATED | E25: =INDEX(Zone_ETo_Assumptions!D5:D8,MATCH("Delta",Zone_ETo_Assumptions!$A$5:$A$8,0)) -> 2.7 | F25: =SUMPRODUCT((Kc_Values!$A$2:$A$75="Beans (dry) / Pulses")*(Kc_Values!$B$2:$B$75="mid_season")*Kc_Values!$E$2:$E$75) -> 1.15 | G25: 110 | H25: =E25*F25*G25 -> 341.55 | I25: =H25*10*0.42 -> 1434.51 | J25: Calculated: FAO24 Table 21 Kc x Zone_ETo_Assumptions x typical season length | K25: Single mid-season-Kc approximation, not a full 4-stage curve - treat as a first-pass estimate, refine using Worked_Example_ETc_Calc method for final numbers.
A26: Faba beans (proxy: Beans dry/Pulses) | B26: Winter | C26: Middle Egypt | D26: ESTIMATED | E26: =INDEX(Zone_ETo_Assumptions!D5:D8,MATCH("Middle Egypt",Zone_ETo_Assumptions!$A$5:$A$8,0)) -> 3 | F26: =SUMPRODUCT((Kc_Values!$A$2:$A$75="Beans (dry) / Pulses")*(Kc_Values!$B$2:$B$75="mid_season")*Kc_Values!$E$2:$E$75) -> 1.15 | G26: 110 | H26: =E26*F26*G26 -> 379.5 | I26: =H26*10*0.42 -> 1593.9 | J26: Calculated: FAO24 Table 21 Kc x Zone_ETo_Assumptions x typical season length | K26: Single mid-season-Kc approximation, not a full 4-stage curve - treat as a first-pass estimate, refine using Worked_Example_ETc_Calc method for final numbers.
A27: Faba beans (proxy: Beans dry/Pulses) | B27: Winter | C27: Upper Egypt | D27: ESTIMATED | E27: =INDEX(Zone_ETo_Assumptions!D5:D8,MATCH("Upper Egypt",Zone_ETo_Assumptions!$A$5:$A$8,0)) -> 3.6 | F27: =SUMPRODUCT((Kc_Values!$A$2:$A$75="Beans (dry) / Pulses")*(Kc_Values!$B$2:$B$75="mid_season")*Kc_Values!$E$2:$E$75) -> 1.15 | G27: 110 | H27: =E27*F27*G27 -> 455.4 | I27: =H27*10*0.42 -> 1912.68 | J27: Calculated: FAO24 Table 21 Kc x Zone_ETo_Assumptions x typical season length | K27: Single mid-season-Kc approximation, not a full 4-stage curve - treat as a first-pass estimate, refine using Worked_Example_ETc_Calc method for final numbers.
A28: Faba beans (proxy: Beans dry/Pulses) | B28: Winter | C28: Sinai / Reclaimed Lands | D28: ESTIMATED | E28: =INDEX(Zone_ETo_Assumptions!D5:D8,MATCH("Sinai / Reclaimed Lands",Zone_ETo_Assumptions!$A$5:$A$8,0)) -> 3 | F28: =SUMPRODUCT((Kc_Values!$A$2:$A$75="Beans (dry) / Pulses")*(Kc_Values!$B$2:$B$75="mid_season")*Kc_Values!$E$2:$E$75) -> 1.15 | G28: 110 | H28: =E28*F28*G28 -> 379.5 | I28: =H28*10*0.42 -> 1593.9 | J28: Calculated: FAO24 Table 21 Kc x Zone_ETo_Assumptions x typical season length | K28: Single mid-season-Kc approximation, not a full 4-stage curve - treat as a first-pass estimate, refine using Worked_Example_ETc_Calc method for final numbers.
A29: Sugar beet | B29: Winter | C29: Delta | D29: ESTIMATED | E29: =INDEX(Zone_ETo_Assumptions!D5:D8,MATCH("Delta",Zone_ETo_Assumptions!$A$5:$A$8,0)) -> 2.7 | F29: =SUMPRODUCT((Kc_Values!$A$2:$A$75="Sugarbeet")*(Kc_Values!$B$2:$B$75="mid_season")*Kc_Values!$E$2:$E$75) -> 1.15 | G29: 180 | H29: =E29*F29*G29 -> 558.9 | I29: =H29*10*0.42 -> 2347.38 | J29: Calculated: FAO24 Table 21 Kc x Zone_ETo_Assumptions x typical season length | K29: Single mid-season-Kc approximation, not a full 4-stage curve - treat as a first-pass estimate, refine using Worked_Example_ETc_Calc method for final numbers.
A30: Sugar beet | B30: Winter | C30: Middle Egypt | D30: ESTIMATED | E30: =INDEX(Zone_ETo_Assumptions!D5:D8,MATCH("Middle Egypt",Zone_ETo_Assumptions!$A$5:$A$8,0)) -> 3 | F30: =SUMPRODUCT((Kc_Values!$A$2:$A$75="Sugarbeet")*(Kc_Values!$B$2:$B$75="mid_season")*Kc_Values!$E$2:$E$75) -> 1.15 | G30: 180 | H30: =E30*F30*G30 -> 621 | I30: =H30*10*0.42 -> 2608.2 | J30: Calculated: FAO24 Table 21 Kc x Zone_ETo_Assumptions x typical season length | K30: Single mid-season-Kc approximation, not a full 4-stage curve - treat as a first-pass estimate, refine using Worked_Example_ETc_Calc method for final numbers.
A31: Sugar beet | B31: Winter | C31: Upper Egypt | D31: ESTIMATED | E31: =INDEX(Zone_ETo_Assumptions!D5:D8,MATCH("Upper Egypt",Zone_ETo_Assumptions!$A$5:$A$8,0)) -> 3.6 | F31: =SUMPRODUCT((Kc_Values!$A$2:$A$75="Sugarbeet")*(Kc_Values!$B$2:$B$75="mid_season")*Kc_Values!$E$2:$E$75) -> 1.15 | G31: 180 | H31: =E31*F31*G31 -> 745.2 | I31: =H31*10*0.42 -> 3129.84 | J31: Calculated: FAO24 Table 21 Kc x Zone_ETo_Assumptions x typical season length | K31: Single mid-season-Kc approximation, not a full 4-stage curve - treat as a first-pass estimate, refine using Worked_Example_ETc_Calc method for final numbers.
A32: Sugar beet | B32: Winter | C32: Sinai / Reclaimed Lands | D32: ESTIMATED | E32: =INDEX(Zone_ETo_Assumptions!D5:D8,MATCH("Sinai / Reclaimed Lands",Zone_ETo_Assumptions!$A$5:$A$8,0)) -> 3 | F32: =SUMPRODUCT((Kc_Values!$A$2:$A$75="Sugarbeet")*(Kc_Values!$B$2:$B$75="mid_season")*Kc_Values!$E$2:$E$75) -> 1.15 | G32: 180 | H32: =E32*F32*G32 -> 621 | I32: =H32*10*0.42 -> 2608.2 | J32: Calculated: FAO24 Table 21 Kc x Zone_ETo_Assumptions x typical season length | K32: Single mid-season-Kc approximation, not a full 4-stage curve - treat as a first-pass estimate, refine using Worked_Example_ETc_Calc method for final numbers.
A33: Onion (dry) | B33: Winter | C33: Delta | D33: ESTIMATED | E33: =INDEX(Zone_ETo_Assumptions!D5:D8,MATCH("Delta",Zone_ETo_Assumptions!$A$5:$A$8,0)) -> 2.7 | F33: =SUMPRODUCT((Kc_Values!$A$2:$A$75="Onion (dry)")*(Kc_Values!$B$2:$B$75="mid_season")*Kc_Values!$E$2:$E$75) -> 1.05 | G33: 150 | H33: =E33*F33*G33 -> 425.25 | I33: =H33*10*0.42 -> 1786.05 | J33: Calculated: FAO24 Table 21 Kc x Zone_ETo_Assumptions x typical season length | K33: Single mid-season-Kc approximation, not a full 4-stage curve - treat as a first-pass estimate, refine using Worked_Example_ETc_Calc method for final numbers.
A34: Onion (dry) | B34: Winter | C34: Middle Egypt | D34: ESTIMATED | E34: =INDEX(Zone_ETo_Assumptions!D5:D8,MATCH("Middle Egypt",Zone_ETo_Assumptions!$A$5:$A$8,0)) -> 3 | F34: =SUMPRODUCT((Kc_Values!$A$2:$A$75="Onion (dry)")*(Kc_Values!$B$2:$B$75="mid_season")*Kc_Values!$E$2:$E$75) -> 1.05 | G34: 150 | H34: =E34*F34*G34 -> 472.5 | I34: =H34*10*0.42 -> 1984.5 | J34: Calculated: FAO24 Table 21 Kc x Zone_ETo_Assumptions x typical season length | K34: Single mid-season-Kc approximation, not a full 4-stage curve - treat as a first-pass estimate, refine using Worked_Example_ETc_Calc method for final numbers.
A35: Onion (dry) | B35: Winter | C35: Upper Egypt | D35: ESTIMATED | E35: =INDEX(Zone_ETo_Assumptions!D5:D8,MATCH("Upper Egypt",Zone_ETo_Assumptions!$A$5:$A$8,0)) -> 3.6 | F35: =SUMPRODUCT((Kc_Values!$A$2:$A$75="Onion (dry)")*(Kc_Values!$B$2:$B$75="mid_season")*Kc_Values!$E$2:$E$75) -> 1.05 | G35: 150 | H35: =E35*F35*G35 -> 567 | I35: =H35*10*0.42 -> 2381.4 | J35: Calculated: FAO24 Table 21 Kc x Zone_ETo_Assumptions x typical season length | K35: Single mid-season-Kc approximation, not a full 4-stage curve - treat as a first-pass estimate, refine using Worked_Example_ETc_Calc method for final numbers.
A36: Onion (dry) | B36: Winter | C36: Sinai / Reclaimed Lands | D36: ESTIMATED | E36: =INDEX(Zone_ETo_Assumptions!D5:D8,MATCH("Sinai / Reclaimed Lands",Zone_ETo_Assumptions!$A$5:$A$8,0)) -> 3 | F36: =SUMPRODUCT((Kc_Values!$A$2:$A$75="Onion (dry)")*(Kc_Values!$B$2:$B$75="mid_season")*Kc_Values!$E$2:$E$75) -> 1.05 | G36: 150 | H36: =E36*F36*G36 -> 472.5 | I36: =H36*10*0.42 -> 1984.5 | J36: Calculated: FAO24 Table 21 Kc x Zone_ETo_Assumptions x typical season length | K36: Single mid-season-Kc approximation, not a full 4-stage curve - treat as a first-pass estimate, refine using Worked_Example_ETc_Calc method for final numbers.
A37: Cotton | B37: Summer | C37: Delta | D37: ESTIMATED | E37: =INDEX(Zone_ETo_Assumptions!E5:E8,MATCH("Delta",Zone_ETo_Assumptions!$A$5:$A$8,0)) -> 5.2 | F37: =SUMPRODUCT((Kc_Values!$A$2:$A$75="Cotton")*(Kc_Values!$B$2:$B$75="mid_season")*Kc_Values!$E$2:$E$75) -> 1.2 | G37: 195 | H37: =E37*F37*G37 -> 1216.8 | I37: =H37*10*0.42 -> 5110.56 | J37: Calculated: FAO24 Table 21 Kc x Zone_ETo_Assumptions x typical season length | K37: Single mid-season-Kc approximation, not a full 4-stage curve - treat as a first-pass estimate, refine using Worked_Example_ETc_Calc method for final numbers.
A38: Cotton | B38: Summer | C38: Middle Egypt | D38: ESTIMATED | E38: =INDEX(Zone_ETo_Assumptions!E5:E8,MATCH("Middle Egypt",Zone_ETo_Assumptions!$A$5:$A$8,0)) -> 6 | F38: =SUMPRODUCT((Kc_Values!$A$2:$A$75="Cotton")*(Kc_Values!$B$2:$B$75="mid_season")*Kc_Values!$E$2:$E$75) -> 1.2 | G38: 195 | H38: =E38*F38*G38 -> 1404 | I38: =H38*10*0.42 -> 5896.8 | J38: Calculated: FAO24 Table 21 Kc x Zone_ETo_Assumptions x typical season length | K38: Single mid-season-Kc approximation, not a full 4-stage curve - treat as a first-pass estimate, refine using Worked_Example_ETc_Calc method for final numbers.
A39: Cotton | B39: Summer | C39: Upper Egypt | D39: ESTIMATED | E39: =INDEX(Zone_ETo_Assumptions!E5:E8,MATCH("Upper Egypt",Zone_ETo_Assumptions!$A$5:$A$8,0)) -> 7.5 | F39: =SUMPRODUCT((Kc_Values!$A$2:$A$75="Cotton")*(Kc_Values!$B$2:$B$75="mid_season")*Kc_Values!$E$2:$E$75) -> 1.2 | G39: 195 | H39: =E39*F39*G39 -> 1755 | I39: =H39*10*0.42 -> 7371 | J39: Calculated: FAO24 Table 21 Kc x Zone_ETo_Assumptions x typical season length | K39: Single mid-season-Kc approximation, not a full 4-stage curve - treat as a first-pass estimate, refine using Worked_Example_ETc_Calc method for final numbers.
A40: Cotton | B40: Summer | C40: Sinai / Reclaimed Lands | D40: ESTIMATED | E40: =INDEX(Zone_ETo_Assumptions!E5:E8,MATCH("Sinai / Reclaimed Lands",Zone_ETo_Assumptions!$A$5:$A$8,0)) -> 6.5 | F40: =SUMPRODUCT((Kc_Values!$A$2:$A$75="Cotton")*(Kc_Values!$B$2:$B$75="mid_season")*Kc_Values!$E$2:$E$75) -> 1.2 | G40: 195 | H40: =E40*F40*G40 -> 1521 | I40: =H40*10*0.42 -> 6388.2 | J40: Calculated: FAO24 Table 21 Kc x Zone_ETo_Assumptions x typical season length | K40: Single mid-season-Kc approximation, not a full 4-stage curve - treat as a first-pass estimate, refine using Worked_Example_ETc_Calc method for final numbers.
A41: Maize | B41: Summer | C41: Delta | D41: ESTIMATED | E41: =INDEX(Zone_ETo_Assumptions!E5:E8,MATCH("Delta",Zone_ETo_Assumptions!$A$5:$A$8,0)) -> 5.2 | F41: =SUMPRODUCT((Kc_Values!$A$2:$A$75="Corn / Maize (grain)")*(Kc_Values!$B$2:$B$75="mid_season")*Kc_Values!$E$2:$E$75) -> 1.15 | G41: 125 | H41: =E41*F41*G41 -> 747.5 | I41: =H41*10*0.42 -> 3139.5 | J41: Calculated: FAO24 Table 21 Kc x Zone_ETo_Assumptions x typical season length | K41: Single mid-season-Kc approximation, not a full 4-stage curve - treat as a first-pass estimate, refine using Worked_Example_ETc_Calc method for final numbers.
A42: Maize | B42: Summer | C42: Middle Egypt | D42: ESTIMATED | E42: =INDEX(Zone_ETo_Assumptions!E5:E8,MATCH("Middle Egypt",Zone_ETo_Assumptions!$A$5:$A$8,0)) -> 6 | F42: =SUMPRODUCT((Kc_Values!$A$2:$A$75="Corn / Maize (grain)")*(Kc_Values!$B$2:$B$75="mid_season")*Kc_Values!$E$2:$E$75) -> 1.15 | G42: 125 | H42: =E42*F42*G42 -> 862.5 | I42: =H42*10*0.42 -> 3622.5 | J42: Calculated: FAO24 Table 21 Kc x Zone_ETo_Assumptions x typical season length | K42: Single mid-season-Kc approximation, not a full 4-stage curve - treat as a first-pass estimate, refine using Worked_Example_ETc_Calc method for final numbers.
A43: Maize | B43: Summer | C43: Upper Egypt | D43: ESTIMATED | E43: =INDEX(Zone_ETo_Assumptions!E5:E8,MATCH("Upper Egypt",Zone_ETo_Assumptions!$A$5:$A$8,0)) -> 7.5 | F43: =SUMPRODUCT((Kc_Values!$A$2:$A$75="Corn / Maize (grain)")*(Kc_Values!$B$2:$B$75="mid_season")*Kc_Values!$E$2:$E$75) -> 1.15 | G43: 125 | H43: =E43*F43*G43 -> 1078.125 | I43: =H43*10*0.42 -> 4528.125 | J43: Calculated: FAO24 Table 21 Kc x Zone_ETo_Assumptions x typical season length | K43: Single mid-season-Kc approximation, not a full 4-stage curve - treat as a first-pass estimate, refine using Worked_Example_ETc_Calc method for final numbers.
A44: Maize | B44: Summer | C44: Sinai / Reclaimed Lands | D44: ESTIMATED | E44: =INDEX(Zone_ETo_Assumptions!E5:E8,MATCH("Sinai / Reclaimed Lands",Zone_ETo_Assumptions!$A$5:$A$8,0)) -> 6.5 | F44: =SUMPRODUCT((Kc_Values!$A$2:$A$75="Corn / Maize (grain)")*(Kc_Values!$B$2:$B$75="mid_season")*Kc_Values!$E$2:$E$75) -> 1.15 | G44: 125 | H44: =E44*F44*G44 -> 934.375 | I44: =H44*10*0.42 -> 3924.375 | J44: Calculated: FAO24 Table 21 Kc x Zone_ETo_Assumptions x typical season length | K44: Single mid-season-Kc approximation, not a full 4-stage curve - treat as a first-pass estimate, refine using Worked_Example_ETc_Calc method for final numbers.
...

Sheet Seasonal_ETcrop_Range
A1: Crop | B1: Seasonal ETcrop Min (mm) | C1: Seasonal ETcrop Max (mm) | D1: Source
A2: Alfalfa | B2: 600 | C2: 1500 | D2: FAO Irrigation & Drainage Paper 24, Table 20
A3: Avocado | B3: 650 | C3: 1000 | D3: FAO Irrigation & Drainage Paper 24, Table 20
A4: Bananas | B4: 700 | C4: 1700 | D4: FAO Irrigation & Drainage Paper 24, Table 20
A5: Beans | B5: 250 | C5: 500 | D5: FAO Irrigation & Drainage Paper 24, Table 20
A6: Cocoa | B6: 800 | C6: 1200 | D6: FAO Irrigation & Drainage Paper 24, Table 20
A7: Coffee | B7: 800 | C7: 1200 | D7: FAO Irrigation & Drainage Paper 24, Table 20
A8: Cotton | B8: 550 | C8: 950 | D8: FAO Irrigation & Drainage Paper 24, Table 20
A9: Dates | B9: 900 | C9: 1300 | D9: FAO Irrigation & Drainage Paper 24, Table 20
A10: Deciduous trees | B10: 700 | C10: 1050 | D10: FAO Irrigation & Drainage Paper 24, Table 20
A11: Flax | B11: 450 | C11: 900 | D11: FAO Irrigation & Drainage Paper 24, Table 20
A12: Grains (small - wheat/barley/oats) | B12: 300 | C12: 450 | D12: FAO Irrigation & Drainage Paper 24, Table 20
A13: Grapefruit | B13: 650 | C13: 1000 | D13: FAO Irrigation & Drainage Paper 24, Table 20
... A30: Walnuts | B30: 700 | C30: 1000 | D30: FAO Irrigation & Drainage Paper 24, Table 20

Sheet Kc_Values
A1: Crop | B1: Stage | C1: Kc (RHmin>70%, wind 0-5 m/s) | D1: Kc (RHmin>70%, wind 5-8 m/s) | E1: Kc (RHmin<20%, wind 0-5 m/s) | F1: Kc (RHmin<20%, wind 5-8 m/s) | G1: Source
A2: Barley | B2: mid_season | C2: 1.05 | D2: 1.1 | E2: 1.15 | F2: 1.2 | G2: FAO Irrigation & Drainage Paper 24, Table 21
A3: Barley | B3: end_season | C3: 0.25 | D3: 0.25 | E3: 0.2 | F3: 0.2 | G3: FAO Irrigation & Drainage Paper 24, Table 21
A4: Beans (green) | B4: mid_season | C4: 0.95 | D4: 0.95 | E4: 1 | F4: 1.05 | G4: FAO Irrigation & Drainage Paper 24, Table 21
A5: Beans (green) | B5: end_season | C5: 0.85 | D5: 0.85 | E5: 0.9 | F5: 0.9 | G5: FAO Irrigation & Drainage Paper 24, Table 21 [OCR-uncertain value in source scan - verify against original PDF page before citing]
A6: Beans (dry) / Pulses | B6: mid_season | C6: 1.05 | D6: 1.1 | E6: 1.15 | F6: 1.2 | G6: FAO Irrigation & Drainage Paper 24, Table 21
A7: Beans (dry) / Pulses | B7: end_season | C7: 0.3 | D7: 0.3 | E7: 0.25 | F7: 0.25 | G7: FAO Irrigation & Drainage Paper 24, Table 21
A8: Beets (table) | B8: mid_season | C8: 1 | D8: 1 | E8: 1.05 | F8: 1.1 | G8: FAO Irrigation & Drainage Paper 24, Table 21
A9: Beets (table) | B9: end_season | C9: 0.9 | D9: 0.9 | E9: 0.95 | F9: 1 | G9: FAO Irrigation & Drainage Paper 24, Table 21
A10: Carrots | B10: mid_season | C10: 1 | D10: 1.05 | E10: 1.1 | F10: 1.15 | G10: FAO Irrigation & Drainage Paper 24, Table 21
A11: Carrots | B11: end_season | C11: 0.7 | D11: 0.75 | E11: 0.8 | F11: 0.85 | G11: FAO Irrigation & Drainage Paper 24, Table 21
A12: Castorbeans | B12: mid_season | C12: 1.05 | D12: 1.1 | E12: 1.15 | F12: 1.2 | G12: FAO Irrigation & Drainage Paper 24, Table 21
A13: Castorbeans | B13: end_season | C13: 0.5 | D13: 0.5 | E13: 0.5 | F13: 0.5 | G13: FAO Irrigation & Drainage Paper 24, Table 21
... A75: Wheat | B75: end_season | C75: 0.25 | D75: 0.25 | E75: 0.2 | F75: 0.2 | G75: FAO Irrigation & Drainage Paper 24, Table 21

Sheet Growth_Stage_Lengths
A1: Crop | B1: Example region / planting window | C1: Initial (days) | D1: Development (days) | E1: Mid-season (days) | F1: Late-season (days) | G1: Total (days) | H1: Source
A2: Wheat/Barley/Oats | B2: Central India, November planting | C2: 15 | D2: 25 | E2: 50 | F2: 30 | G2: 120 | H2: FAO Irrigation & Drainage Paper 24, Table 22
A3: Wheat/Barley/Oats | B3: East African highlands, July planting | C3: 15 | D3: 30 | E3: 65 | F3: 40 | G3: 150 | H3: FAO Irrigation & Drainage Paper 24, Table 22
A4: Beans (green) | B4: Aug-Sep planting: California desert, Egypt, Coastal Lebanon | C4: 15 | D4: 25 | E4: 25 | F4: 10 | G4: 75 | H4: FAO Irrigation & Drainage Paper 24, Table 22
A5: Beans (green) | B5: Feb-Mar planting: California desert, Mediterranean | C5: 20 | D5: 30 | E5: 30 | F5: 10 | G5: 90 | H5: FAO Irrigation & Drainage Paper 24, Table 22
A6: Cotton | B6: March planting Egypt / April-May Pakistan / Sept planting South Arabia | C6: 30 | D6: 50 | E6: 60 | F6: 55 | G6: 195 | H6: FAO Irrigation & Drainage Paper 24, Table 22
A7: Cotton | B7: Spring planting, machine harvested, Texas | C7: 30 | D7: 50 | E7: 55 | F7: 45 | G7: 180 | H7: FAO Irrigation & Drainage Paper 24, Table 22
A8: Cucumber | B8: June planting Egypt / Aug-Oct California desert | C8: 20 | D8: 30 | E8: 40 | F8: 15 | G8: 105 | H8: FAO Irrigation & Drainage Paper 24, Table 22
A9: Corn (maize, grain) | B9: June planting sub-humid Nigeria / early Oct India | C9: 20 | D9: 35 | E9: 40 | F9: 30 | G9: 125 | H9: FAO Irrigation & Drainage Paper 24, Table 22
A10: Corn (maize, grain) | B10: April planting Southern Spain | C10: 30 | D10: 40 | E10: 50 | F10: 30 | G10: 150 | H10: FAO Irrigation & Drainage Paper 24, Table 22
A11: Sugarbeet | B11: Early spring planting, Uruguay | C11: 30 | D11: 45 | E11: 60 | F11: 45 | G11: 180 | H11: FAO Irrigation & Drainage Paper 24, Table 22
A12: Sugarbeet | B12: Late winter planting, warm winter desert | C12: 35 | D12: 60 | E12: 70 | F12: 40 | G12: 205 | H12: FAO Irrigation & Drainage Paper 24, Table 22
A13: Onion (dry) | B13: Spring planting, Mediterranean climates | C13: 15 | D13: 25 | E13: 70 | F13: 40 | G13: 150 | H13: FAO Irrigation & Drainage Paper 24, Table 22
... A20: Peanuts (groundnuts) | B20: Dry season planting, West Africa | C20: 25 | D20: 35 | E20: 45 | F20: 25 | G20: 130 | H20: FAO Irrigation & Drainage Paper 24, Table 22
A22: Note: this is a SELECTED subset of Table 22 (entries with clear Egypt relevance or major crops). The full table in the source PDF covers ~40 crops; see the FAO24 PDF pages 42-44 for the complete list.

Sheet Sinai_Egypt_NIWR
A1: Crop | B1: Season | C1: Region Code | D1: Region Name | E1: Soil Type | F1: NIWR (mm) | G1: NIWR (m3/feddan) [calculated] | H1: Source
A2: Tomato | B2: summer | C2: AER1 | D2: Tina Plain | E2: clay | F2: 711 | G2: =F2*10*0.42 -> 2986.2 | H2: Gabr & Fattouh (2021), Ain Shams Engineering Journal 12(2):1623-1636
A3: Cotton | B3: summer | C3: AER1 | D3: Tina Plain | E3: clay | F3: 884 | G3: =F3*10*0.42 -> 3712.8 | H3: Gabr & Fattouh (2021), Ain Shams Engineering Journal 12(2):1623-1636
A4: Sugarbeet | B4: summer | C4: AER1 | D4: Tina Plain | E4: clay | F4: 506 | G4: =F4*10*0.42 -> 2125.2 | H4: Gabr & Fattouh (2021), Ain Shams Engineering Journal 12(2):1623-1636
A5: Maize | B5: summer | C5: AER1 | D5: Tina Plain | E5: clay | F5: 576 | G5: =F5*10*0.42 -> 2419.2 | H5: Gabr & Fattouh (2021), Ain Shams Engineering Journal 12(2):1623-1636
A6: Berseem clover | B6: winter | C6: AER2 | D6: East South El-Kantara | E6: sandy | F6: 702 | G6: =F6*10*0.42 -> 2948.4 | H6: Gabr & Fattouh (2021), Ain Shams Engineering Journal 12(2):1623-1636
A7: Barley | B7: winter | C7: AER2 | D7: East South El-Kantara | E7: sandy | F7: 267 | G7: =F7*10*0.42 -> 1121.4 | H7: Gabr & Fattouh (2021), Ain Shams Engineering Journal 12(2):1623-1636
A8: Greenbeans | B8: winter | C8: AER2 | D8: East South El-Kantara | E8: sandy | F8: 211 | G8: =F8*10*0.42 -> 886.2 | H8: Gabr & Fattouh (2021), Ain Shams Engineering Journal 12(2):1623-1636
A9: Wheat | B9: winter | C9: AER2 | D9: East South El-Kantara | E9: sandy | F9: 263 | G9: =F9*10*0.42 -> 1104.6 | H9: Gabr & Fattouh (2021), Ain Shams Engineering Journal 12(2):1623-1636
A10: Tomato | B10: winter | C10: AER2 | D10: East South El-Kantara | E10: sandy | F10: 448 | G10: =F10*10*0.42 -> 1881.6 | H10: Gabr & Fattouh (2021), Ain Shams Engineering Journal 12(2):1623-1636
A11: Tomato | B11: summer | C11: AER2 | D11: East South El-Kantara | E11: sandy | F11: 884 | G11: =F11*10*0.42 -> 3712.8 | H11: Gabr & Fattouh (2021), Ain Shams Engineering Journal 12(2):1623-1636
A12: Cotton | B12: summer | C12: AER2 | D12: East South El-Kantara | E12: sandy | F12: 1107 | G12: =F12*10*0.42 -> 4649.4 | H12: Gabr & Fattouh (2021), Ain Shams Engineering Journal 12(2):1623-1636
A13: Sugarbeet | B13: summer | C13: AER2 | D13: East South El-Kantara | E13: sandy | F13: 560 | G13: =F13*10*0.42 -> 2352 | H13: Gabr & Fattouh (2021), Ain Shams Engineering Journal 12(2):1623-1636
... A17: Cotton | B17: summer | C17: AER1 | D17: Tina Plain | E17: clay | F17: 901 | G17: =F17*10*0.42 -> 3784.2 | H17: Gabr & Fattouh (2021), Ain Shams Engineering Journal 12(2):1623-1636
A19: NIWR = Net Irrigation Water Requirement (after subtracting effective rainfall). Paper models surface irrigation efficiency of 40% (AER1, clay) and 60% (AER2, sandy/drip/sprinkler) - divide NIWR by that efficiency to estimate GROSS water applied, if your model tracks gross rather than net.
A20: m3/feddan column is a CALCULATED conversion (mm x 10 = m3/ha, x 0.42 = m3/feddan) using a live formula - not directly extracted from the source paper, which reports only mm.

Sheet Worked_Example_ETc_Calc
A1: Worked example: Wheat, arid climate (Egypt), stage-by-stage ETc calculation
A2: Yellow cells = edit with your farmer's real location/ETo data. This demonstrates ETc(t) = Kc(t) x ETo(t), summed by stage - not a single constant.
A4: Stage | B4: Days | C4: Kc (RHmin<20%, wind 0-5 m/s) | D4: Assumed ETo (mm/day) [EDIT ME] | E4: Stage ETc (mm) | F4: Notes
A5: Initial | B5: 15 | C5: =0.3 -> 0.3 | D5: 3 | E5: =C5*D5*B5 -> 13.5 | F5: Kc-initial is NOT a Table 21 constant - depends on irrigation frequency and ETo level (Fig. 6 in source). 0.3 is a typical cereal placeholder; refine with Fig. 6 or local data.
A6: Development | B6: 25 | C6: =(C5+C7)/2 -> 0.725 | D6: 3.5 | E6: =C6*D6*B6 -> 63.4375 | F6: Linear interpolation between initial-stage Kc and mid-season Kc, per FAO-24 methodology.
A7: Mid-season | B7: 50 | C7: 1.15 | D7: 4.5 | E7: =C7*D7*B7 -> 258.75 | F7: From Kc_Values sheet: Wheat, mid_season, RHmin<20%, wind 0-5 m/s.
A8: Late-season | B8: 30 | C8: =(C7+C10)/2 -> 0.675 | D8: 5 | E8: =C8*D8*B8 -> 101.25 | F8: Interpolation between mid-season Kc and end-season Kc (helper cell C10).
A10: TOTAL SEASONAL ETc | B10: =SUM(B5:B8) -> 120 | C10: 0.2 | E10: =SUM(E5:E8) -> 436.9375
A12: Sanity check vs. Table 20 range for 'Grains (small)': | C12: 300 - 450 mm (Seasonal_ETcrop_Range sheet)
A13: Within range? | C13: =IF(AND(E10>=300,E10<=450),"YES","CHECK - outside typical range") -> YES
